Traceback (most recent call last):
  File "/public/home/sll/miniconda3/lib/python3.10/site-packages/jupyter_cache/executors/utils.py", line 58, in single_nb_execution
    executenb(
  File "/public/home/sll/miniconda3/lib/python3.10/site-packages/nbclient/client.py", line 1305, in execute
    return NotebookClient(nb=nb, resources=resources, km=km, **kwargs).execute()
  File "/public/home/sll/miniconda3/lib/python3.10/site-packages/jupyter_core/utils/__init__.py", line 173, in wrapped
    return loop.run_until_complete(inner)
  File "/public/home/sll/miniconda3/lib/python3.10/asyncio/base_events.py", line 649, in run_until_complete
    return future.result()
  File "/public/home/sll/miniconda3/lib/python3.10/site-packages/nbclient/client.py", line 705, in async_execute
    await self.async_execute_cell(
  File "/public/home/sll/miniconda3/lib/python3.10/site-packages/nbclient/client.py", line 1058, in async_execute_cell
    await self._check_raise_for_error(cell, cell_index, exec_reply)
  File "/public/home/sll/miniconda3/lib/python3.10/site-packages/nbclient/client.py", line 914, in _check_raise_for_error
    raise CellExecutionError.from_cell_and_msg(cell, exec_reply_content)
nbclient.exceptions.CellExecutionError: An error occurred while executing the following cell:
------------------
list1 <- list(a=c(5, 10),
             b=c("I", "love", "R", "language", "!"),
             c=c(TRUE, TRUE, FALSE, TRUE))
list1
list1$a
list1$`b[2]
------------------


Error in parse(text = x, srcfile = src): <text>:6:7: 意外的INCOMPLETE_STRING
5: list1$a
6: list1$`b[2]
         ^
Traceback:


